<?xml version="1.0"?>

<robot xmlns="http://drake.mit.edu"
       xmlns:xsi="http://www.w3.org/2001/XMLSchema-instance"
       xsi:schemaLocation="http://drake.mit.edu ../../doc/drakeURDF.xsd"
       name="Ten Segment 2D">

  <link name="base_link">
    <visual>
      <geometry>
        <box size="0.5 0.5 0.5"/>
      </geometry>
      <material name="green">
        <color rgba="0 1 0 1"/>
      </material>
    </visual>
  </link>

  <link name="link_1">
    <inertial>
      <origin xyz="0 0 -0.5" rpy="0 0 0"/>
      <mass value="1"/>
      <inertia ixx="0.086" ixy="0" ixz="0" iyy="0.086" iyz="0" izz="0.005"/>
    </inertial>
    <visual>
      <origin xyz="0 0 -0.5" rpy="0 0 0"/>
      <geometry>
        <cylinder length="1" radius="0.1"/>
      </geometry>
      <material name="red">
        <color rgba="1 0 0 1"/>
      </material>
    </visual>
  </link>

  <link name="link_2">
    <inertial>
      <origin xyz="0 0 -0.5" rpy="0 0 0"/>
      <mass value="1"/>
      <inertia ixx="0.086" ixy="0" ixz="0" iyy="0.086" iyz="0" izz="0.005"/>
    </inertial>
    <visual>
      <origin xyz="0 0 -0.5" rpy="0 0 0"/>
      <geometry>
        <cylinder length="1" radius="0.1"/>
      </geometry>
      <material name="blue">
        <color rgba="0 0 1 1"/>
      </material>
    </visual>
  </link>

  <link name="link_3">
    <inertial>
      <origin xyz="0 0 -0.5" rpy="0 0 0"/>
      <mass value="1"/>
      <inertia ixx="0.086" ixy="0" ixz="0" iyy="0.086" iyz="0" izz="0.005"/>
    </inertial>
    <visual>
      <origin xyz="0 0 -0.5" rpy="0 0 0"/>
      <geometry>
        <cylinder length="1" radius="0.1"/>
      </geometry>
      <material name="red"/>
    </visual>
  </link>

  <link name="link_4">
    <inertial>
      <origin xyz="0 0 -0.5" rpy="0 0 0"/>
      <mass value="1"/>
      <inertia ixx="0.086" ixy="0" ixz="0" iyy="0.086" iyz="0" izz="0.005"/>
    </inertial>
    <visual>
      <origin xyz="0 0 -0.5" rpy="0 0 0"/>
      <geometry>
        <cylinder length="1" radius="0.1"/>
      </geometry>
      <material name="blue"/>
    </visual>
  </link>

  <link name="link_5">
    <inertial>
      <origin xyz="0 0 -0.5" rpy="0 0 0"/>
      <mass value="1"/>
      <inertia ixx="0.086" ixy="0" ixz="0" iyy="0.086" iyz="0" izz="0.005"/>
    </inertial>
    <visual>
      <origin xyz="0 0 -0.5" rpy="0 0 0"/>
      <geometry>
        <cylinder length="1" radius="0.1"/>
      </geometry>
      <material name="red"/>
    </visual>
  </link>

  <link name="link_6">
    <inertial>
      <origin xyz="0 0 -0.5" rpy="0 0 0"/>
      <mass value="1"/>
      <inertia ixx="0.086" ixy="0" ixz="0" iyy="0.086" iyz="0" izz="0.005"/>
    </inertial>
    <visual>
      <origin xyz="0 0 -0.5" rpy="0 0 0"/>
      <geometry>
        <cylinder length="1" radius="0.1"/>
      </geometry>
      <material name="blue"/>
    </visual>
  </link>

  <link name="link_7">
    <inertial>
      <origin xyz="0 0 -0.5" rpy="0 0 0"/>
      <mass value="1"/>
      <inertia ixx="0.086" ixy="0" ixz="0" iyy="0.086" iyz="0" izz="0.005"/>
    </inertial>
    <visual>
      <origin xyz="0 0 -0.5" rpy="0 0 0"/>
      <geometry>
        <cylinder length="1" radius="0.1"/>
      </geometry>
      <material name="red"/>
    </visual>
  </link>

  <link name="link_8">
    <inertial>
      <origin xyz="0 0 -0.5" rpy="0 0 0"/>
      <mass value="1"/>
      <inertia ixx="0.086" ixy="0" ixz="0" iyy="0.086" iyz="0" izz="0.005"/>
    </inertial>
    <visual>
      <origin xyz="0 0 -0.5" rpy="0 0 0"/>
      <geometry>
        <cylinder length="1" radius="0.1"/>
      </geometry>
      <material name="blue"/>
    </visual>
  </link>

  <link name="link_9">
    <inertial>
      <origin xyz="0 0 -0.5" rpy="0 0 0"/>
      <mass value="1"/>
      <inertia ixx="0.086" ixy="0" ixz="0" iyy="0.086" iyz="0" izz="0.005"/>
    </inertial>
    <visual>
      <origin xyz="0 0 -0.5" rpy="0 0 0"/>
      <geometry>
        <cylinder length="1" radius="0.1"/>
      </geometry>
      <material name="red"/>
    </visual>
  </link>

  <link name="link_10">
    <inertial>
      <origin xyz="0 0 -0.5" rpy="0 0 0"/>
      <mass value="1"/>
      <inertia ixx="0.086" ixy="0" ixz="0" iyy="0.086" iyz="0" izz="0.005"/>
    </inertial>
    <visual>
      <origin xyz="0 0 -0.5" rpy="0 0 0"/>
      <geometry>
        <cylinder length="1" radius="0.1"/>
      </geometry>
      <material name="blue"/>
    </visual>
  </link>

  <joint name="joint_1" type="continuous">
    <parent link="base_link"/>
    <child link="link_1"/>
    <origin xyz="0 0.35 0"/>
    <axis xyz="0 1 0"/>
    <dynamics damping="0.1"/>
  </joint>

  <joint name="joint_2" type="continuous">
    <parent link="link_1"/>
    <child link="link_2"/>
    <origin xyz="0 0 -1"/>
    <axis xyz="0 1 0"/>
    <dynamics damping="0.1"/>
  </joint>

  <joint name="joint_3" type="continuous">
    <parent link="link_2"/>
    <child link="link_3"/>
    <origin xyz="0 0 -1"/>
    <axis xyz="0 1 0"/>
    <dynamics damping="0.1"/>
  </joint>

  <joint name="joint_4" type="continuous">
    <parent link="link_3"/>
    <child link="link_4"/>
    <origin xyz="0 0 -1"/>
    <axis xyz="0 1 0"/>
    <dynamics damping="0.1"/>
  </joint>

  <joint name="joint_5" type="continuous">
    <parent link="link_4"/>
    <child link="link_5"/>
    <origin xyz="0 0 -1"/>
    <axis xyz="0 1 0"/>
    <dynamics damping="0.1"/>
  </joint>

  <joint name="joint_6" type="continuous">
    <parent link="link_5"/>
    <child link="link_6"/>
    <origin xyz="0 0 -1"/>
    <axis xyz="0 1 0"/>
    <dynamics damping="0.1"/>
  </joint>

  <joint name="joint_7" type="continuous">
    <parent link="link_6"/>
    <child link="link_7"/>
    <origin xyz="0 0 -1"/>
    <axis xyz="0 1 0"/>
    <dynamics damping="0.1"/>
  </joint>

  <joint name="joint_8" type="continuous">
    <parent link="link_7"/>
    <child link="link_8"/>
    <origin xyz="0 0 -1"/>
    <axis xyz="0 1 0"/>
    <dynamics damping="0.1"/>
  </joint>

  <joint name="joint_9" type="continuous">
    <parent link="link_8"/>
    <child link="link_9"/>
    <origin xyz="0 0 -1"/>
    <axis xyz="0 1 0"/>
    <dynamics damping="0.1"/>
  </joint>

  <joint name="joint_10" type="continuous">
    <parent link="link_9"/>
    <child link="link_10"/>
    <origin xyz="0 0 -1"/>
    <axis xyz="0 1 0"/>
    <dynamics damping="0.1"/>
  </joint>

</robot>
